{"metadata":{"kernelspec":{"language":"python","display_name":"Python 3","name":"python3"},"language_info":{"name":"python","version":"3.10.13","mimetype":"text/x-python","codemirror_mode":{"name":"ipython","version":3},"pygments_lexer":"ipython3","nbconvert_exporter":"python","file_extension":".py"},"kaggle":{"accelerator":"gpu","dataSources":[{"sourceId":8454973,"sourceType":"datasetVersion","datasetId":5039034},{"sourceId":8642541,"sourceType":"datasetVersion","datasetId":4423272},{"sourceId":8679914,"sourceType":"datasetVersion","datasetId":5072230},{"sourceId":8680185,"sourceType":"datasetVersion","datasetId":5203378}],"dockerImageVersionId":30733,"isInternetEnabled":true,"language":"python","sourceType":"notebook","isGpuEnabled":true}},"nbformat_minor":4,"nbformat":4,"cells":[{"cell_type":"code","source":"!python /kaggle/input/deployment/app.py","metadata":{"execution":{"iopub.status.busy":"2024-06-13T07:34:10.089245Z","iopub.execute_input":"2024-06-13T07:34:10.089608Z","iopub.status.idle":"2024-06-13T07:34:16.034397Z","shell.execute_reply.started":"2024-06-13T07:34:10.089577Z","shell.execute_reply":"2024-06-13T07:34:16.033454Z"},"trusted":true},"execution_count":3,"outputs":[{"name":"stdout","text":"2024-06-13 07:34:11.595377: E external/local_xla/xla/stream_executor/cuda/cuda_dnn.cc:9261] Unable to register cuDNN factory: Attempting to register factory for plugin cuDNN when one has already been registered\n2024-06-13 07:34:11.595433: E external/local_xla/xla/stream_executor/cuda/cuda_fft.cc:607] Unable to register cuFFT factory: Attempting to register factory for plugin cuFFT when one has already been registered\n2024-06-13 07:34:11.596896: E external/local_xla/xla/stream_executor/cuda/cuda_blas.cc:1515] Unable to register cuBLAS factory: Attempting to register factory for plugin cuBLAS when one has already been registered\nTraceback (most recent call last):\n  File \"/opt/conda/lib/python3.10/site-packages/keras/src/ops/operation.py\", line 208, in from_config\n    return cls(**config)\n  File \"/opt/conda/lib/python3.10/site-packages/keras/src/layers/convolutional/depthwise_conv2d.py\", line 118, in __init__\n    super().__init__(\n  File \"/opt/conda/lib/python3.10/site-packages/keras/src/layers/convolutional/base_depthwise_conv.py\", line 106, in __init__\n    super().__init__(\n  File \"/opt/conda/lib/python3.10/site-packages/keras/src/layers/layer.py\", line 264, in __init__\n    raise ValueError(\nValueError: Unrecognized keyword arguments passed to DepthwiseConv2D: {'groups': 1}\n\nDuring handling of the above exception, another exception occurred:\n\nTraceback (most recent call last):\n  File \"/kaggle/input/deployment/app.py\", line 22, in <module>\n    model = load_model('/kaggle/input/my-model/my_model (1).h5')\n  File \"/opt/conda/lib/python3.10/site-packages/keras/src/saving/saving_api.py\", line 183, in load_model\n    return legacy_h5_format.load_model_from_hdf5(\n  File \"/opt/conda/lib/python3.10/site-packages/keras/src/legacy/saving/legacy_h5_format.py\", line 133, in load_model_from_hdf5\n    model = saving_utils.model_from_config(\n  File \"/opt/conda/lib/python3.10/site-packages/keras/src/legacy/saving/saving_utils.py\", line 85, in model_from_config\n    return serialization.deserialize_keras_object(\n  File \"/opt/conda/lib/python3.10/site-packages/keras/src/legacy/saving/serialization.py\", line 495, in deserialize_keras_object\n    deserialized_obj = cls.from_config(\n  File \"/opt/conda/lib/python3.10/site-packages/keras/src/models/model.py\", line 517, in from_config\n    return functional_from_config(\n  File \"/opt/conda/lib/python3.10/site-packages/keras/src/models/functional.py\", line 517, in functional_from_config\n    process_layer(layer_data)\n  File \"/opt/conda/lib/python3.10/site-packages/keras/src/models/functional.py\", line 497, in process_layer\n    layer = saving_utils.model_from_config(\n  File \"/opt/conda/lib/python3.10/site-packages/keras/src/legacy/saving/saving_utils.py\", line 85, in model_from_config\n    return serialization.deserialize_keras_object(\n  File \"/opt/conda/lib/python3.10/site-packages/keras/src/legacy/saving/serialization.py\", line 504, in deserialize_keras_object\n    deserialized_obj = cls.from_config(cls_config)\n  File \"/opt/conda/lib/python3.10/site-packages/keras/src/ops/operation.py\", line 210, in from_config\n    raise TypeError(\nTypeError: Error when deserializing class 'DepthwiseConv2D' using config={'name': 'expanded_conv_depthwise', 'trainable': False, 'dtype': 'float32', 'kernel_size': [3, 3], 'strides': [1, 1], 'padding': 'same', 'data_format': 'channels_last', 'dilation_rate': [1, 1], 'groups': 1, 'activation': 'linear', 'use_bias': False, 'bias_initializer': {'module': 'keras.initializers', 'class_name': 'Zeros', 'config': {}, 'registered_name': None}, 'bias_regularizer': None, 'activity_regularizer': None, 'bias_constraint': None, 'depth_multiplier': 1, 'depthwise_initializer': {'module': 'keras.initializers', 'class_name': 'GlorotUniform', 'config': {'seed': None}, 'registered_name': None}, 'depthwise_regularizer': None, 'depthwise_constraint': None}.\n\nException encountered: Unrecognized keyword arguments passed to DepthwiseConv2D: {'groups': 1}\n","output_type":"stream"}]},{"cell_type":"code","source":"!curl -X POST -H \"Content-Type: application/json\" -d '{\"image_paths\": [\"/kaggle/input/testimage/Pelargonium_capitatum1.jpg\"], \"top_k\": 5}' http://127.0.0.1:5000/predict","metadata":{"execution":{"iopub.status.busy":"2024-06-13T07:36:05.576151Z","iopub.execute_input":"2024-06-13T07:36:05.576490Z","iopub.status.idle":"2024-06-13T07:36:06.526211Z","shell.execute_reply.started":"2024-06-13T07:36:05.576463Z","shell.execute_reply":"2024-06-13T07:36:06.525140Z"},"trusted":true},"execution_count":5,"outputs":[{"name":"stdout","text":"curl: (7) Failed to connect to 127.0.0.1 port 5000 after 0 ms: Couldn't connect to server\n","output_type":"stream"}]}]}